Workbook

Sheet Plantilla Padrón
A1: Rojo: Campo obligatorio Blanco: Campo opcional | B1: CURP | C1: PRIMER APELLIDO | D1: SEGUNDO APELLIDO | E1: NOMBRE | F1: FECHA DE NACIMIENTO | G1: SEXO | H1: GENERO | I1: ESTADO CIVIL | J1: ORIGEN AFRODECENDIENTE | K1: LENGUA INDIGENA | L1: GRUPO INDIGENA | M1: TELEFONO | N1: CORREO ELECTRONICO | O1: NACIONALIDAD | P1: ESCOLARIDAD | Q1: OCUPACIÓN | R1: DISCAPACIDAD | S1: PORCENTAJE DE DISCAPACIDAD (SOLO CON CERTIFICADO) | T1: ESTADO DE NACIMIENTO | U1: TIPO DE VIALIDAD | V1: NOMBRE DE VIALIDAD | W1: NUMERO EXTERIOR | X1: LETRA ESXTERIOR | Y1: NUMERO INTERIOR | Z1: LETRA INTERIOR | AA1: CODIGO POSTAL | AB1: ENTIDAD | AC1: MUNICIPIO | AD1: LOCALIDAD | AE1: TIPO DE ASENTAMIENTO | AF1: TIPO DE VIALIDAD CALLE PRINCIPAL | AG1: NOMBRE DE CALLE PRINCIPAL | AH1: TIPO DE VIALIDAD SECUNDARIA | AI1: NOMBRE DE CALLE SECUNDARIA | AJ1: TIPO DE VIALIDAD TERCIARIA | AK1: NOMBRE DE CALLE TERCIARIA | AL1: APOYO SOCIAL (RACIONES) | AM1: SERVICIOS DE SALUD | AN1: TRABAJO SOCIAL | AO1: SESIONES TALLERES Y ACTIVIDADES | AP1: TRASLADOS | AQ1: ACTIVIDAD INTERGENERACIONAL | AR1: PSICOLOGIA | AS1: JURIDICO | AT1: INGRESOS AL PADRON | AU1: Monto en pesos del beneficio o apoyo en especie entregado
B2: CURP990630HJCRRV00 | C2: GOMEZ | D2: PEREZ | E2: GUADALUPE | F2: 24160 | G2: MUJER | H2: MUXE | I2: SOLTERA(O) | J2: SI | O2: MEXICANA | P2: PRIMARIA | Q2: NINGUNA | R2: DISCAPACIDAD VISUAL | T2: JALISCO | U2: BOULEVARD | AA2: 44840 | AB2: JALISCO | AC2: ACATIC | AD2: El Capadero (San Miguel de la Loza) | AE2: CANTÓN | AJ2: CALZADA | AK2: CALLE 3

Sheet Plantilla formateada
A1: curp | B1: primer_ap | C1: segundo_ap | D1: nombre | E1: fh_nacimiento | F1: id_sexo | G1: id_genero | H1: id_est_civil | I1: origen_afro | J1: clave_leng_indi | K1: clave_grupo_indi | L1: tel | M1: email | N1: id_nacionalidad | O1: id_escolaridad | P1: id_ocupacion | Q1: id_discapacidad | R1: porc_discapacidad | S1: id_edo_nac | T1: id_vial | U1: nomvial | V1: num_ext | W1: let_ext | X1: num_int | Y1: let_int | Z1: cp | AA1: clave_ent | AB1: clave_mun | AC1: clave_loc | AD1: id_asen | AE1: id_tipo_ref1 | AF1: nom1 | AG1: id_tipo_ref2 | AH1: nom2 | AI1: id_tipo_ref3 | AJ1: nom3
A2: =IFERROR( IF(AND(LEN('Plantilla Padrón'!B2)=18, ISERROR(FIND(" ",'Plantilla Padrón'!B2)), ISERROR(FIND("?",'Plantilla Padrón'!B2)), ISERROR(FIND("¡",'Plantilla Padrón'!B2)), ISERROR(FIND("!",'Plantilla Padrón'!B2)), ISERROR(FIND(".",'Plantilla Padrón'!B2)), ISERROR(FIND(",",'Plantilla Padrón'!B2)), ISERROR(FIND(";",'Plantilla Padrón'!B2)), ISERROR(FIND(":",'Plantilla Padrón'!B2)), ISERROR(FIND("(",'Plantilla Padrón'!B2)), ISERROR(FIND(")",'Plantilla Padrón'!B2)), ISERROR(FIND("-",'Plantilla Padrón'!B2)), ISERROR(FIND("_",'Plantilla Padrón'!B2)), ISERROR(FIND("=",'Plantilla Padrón'!B2)), ISERROR(FIND("+",'Plantilla Padrón'!B2)), ISERROR(FIND("[",'Plantilla Padrón'!B2)), ISERROR(FIND("]",'Plantilla Padrón'!B2)), ISERROR(FIND("{",'Plantilla Padrón'!B2)), ISERROR(FIND("}",'Plantilla Padrón'!B2)), ISERROR(FIND("|",'Plantilla Padrón'!B2)), ISERROR(FIND("@",'Plantilla Padrón'!B2)), ISERROR(FIND("#",'Plantilla Padrón'!B2)), ISERROR(FIND("$",'Plantilla Padrón'!B2)), ISERROR(FIND("%",'Plantilla Padrón'!B2)), ISERROR(FIND("&",'Plantilla Padrón'!B2)), ISERROR(FIND("/",'Plantilla Padrón'!B2)), ISERROR(FIND("\",'Plantilla Padrón'!B2)) ), 'Plantilla Padrón'!B2, "La CURP no es correcta" ), "La CURP no es correcta" ) -> CURP990630HJCRRV00 | B2: ='Plantilla Padrón'!C2 -> GOMEZ | C2: ='Plantilla Padrón'!D2 -> PEREZ | D2: ='Plantilla Padrón'!E2 -> GUADALUPE | E2: ='Plantilla Padrón'!F2 -> 24160 | F2: =INDEX(Catalogos!A2:A6, MATCH(TRIM('Plantilla Padrón'!G2), Catalogos!$B$2:$B$6, 0)) -> 2 | G2: =INDEX(Catalogos!$AB$3:$AB$11, MATCH(TRIM('Plantilla Padrón'!H2), Catalogos!$AC$3:$AC$11, 0)) -> 6 | H2: =INDEX(Catalogos!$AE$3:AE$9, MATCH(TRIM('Plantilla Padrón'!I2), Catalogos!$AF$3:$AF$9, 0)) -> 1 | I2: =INDEX(Catalogos!$AN$3:$AN$4, MATCH(TRIM('Plantilla Padrón'!J2), Catalogos!$AO$3:$AO$4, 0)) -> 1 | J2: =IFERROR(INDEX(Catalogos!$V$3:$V$98, MATCH(TRIM('Plantilla Padrón'!K2), Catalogos!$W$3:$W$98, 0)),"NULL") -> NULL | K2: =IFERROR(INDEX(Catalogos!$Y$3:$Y$46, MATCH(TRIM('Plantilla Padrón'!L2), Catalogos!$Z$3:$Z$46, 0)),"NULL") -> NULL | L2: ='Plantilla Padrón'!M2 | M2: ='Plantilla Padrón'!N2 | N2: =INDEX(Catalogos!$P$3:$P$174, MATCH(TRIM('Plantilla Padrón'!O2), Catalogos!$Q$3:$Q$174, 0)) -> 223 | O2: =INDEX(Catalogos!$AH$3:$AH$11, MATCH(TRIM('Plantilla Padrón'!P2), Catalogos!$AI$3:$AI$11, 0)) -> 2 | P2: =INDEX(Catalogos!$M$3:$M$19, MATCH(TRIM('Plantilla Padrón'!Q2), Catalogos!$N$3:$N$19, 0)) -> 1 | Q2: =INDEX(Catalogos!$D$3:$D$15, MATCH(TRIM('Plantilla Padrón'!R2),Catalogos!$E$3:$E$15, 0)) -> 3 | R2: ='Plantilla Padrón'!S2 | S2: =INDEX(Catalogos!$AK$3:$AK$37, MATCH(TRIM('Plantilla Padrón'!T2),Catalogos!$AL$3:$AL$37, 0)) -> 14 | T2: =INDEX(Catalogos!$J$3:$J$38, MATCH(TRIM('Plantilla Padrón'!U2),Catalogos!$K$3:$K$38, 0)) -> 4 | U2: ='Plantilla Padrón'!V2 | V2: ='Plantilla Padrón'!W2 | W2: ='Plantilla Padrón'!X2 | X2: ='Plantilla Padrón'!Y2 | Y2: ='Plantilla Padrón'!Z2 | Z2: ='Plantilla Padrón'!AA2 -> 44840 | AA2: =INDEX(Catalogos!$AK$3:$AK$37, MATCH(TRIM('Plantilla Padrón'!AB2),Catalogos!$AL$3:$AL$37, 0)) -> 14 | AB2: =INDEX(Catalogos!$AQ$3:$AQ$127, MATCH(TRIM('Plantilla Padrón'!AC2),Catalogos!$AR$3:$AR$127, 0)) -> 1 | AC2: =INDEX(Catalogos!$S$3:$S$20655, MATCH(TRIM('Plantilla Padrón'!AD2),Catalogos!$T$3:$T$20655, 0)) -> 10 | AD2: =INDEX(Catalogos!$G$3:$G$44, MATCH(TRIM('Plantilla Padrón'!AE2),Catalogos!$H$3:$H$44, 0)) -> 4 | AE2: =IFERROR(INDEX(Catalogos!$J$3:$J$38, MATCH(TRIM('Plantilla Padrón'!AF2),Catalogos!$K$3:$K$38, 0)),"NULL") -> NULL | AF2: ='Plantilla Padrón'!AG2 | AG2: =IFERROR(INDEX(Catalogos!$J$3:$J$38, MATCH(TRIM('Plantilla Padrón'!AH2),Catalogos!$K$3:$K$38, 0)),"NULL") -> NULL | AH2: ='Plantilla Padrón'!AI2 | AI2: =IFERROR(INDEX(Catalogos!$J$3:$J$38, MATCH(TRIM('Plantilla Padrón'!AJ2),Catalogos!$K$3:$K$38, 0)),"NULL") -> 7 | AJ2: ='Plantilla Padrón'!AK2 -> CALLE 3

Sheet Catalogos
A1: Sexos | D1: Discapacidades | G1: Asentamientos | J1: Vialidades | M1: Ocupaciones | P1: Nacionalidades | S1: Localidades | V1: Lenguas indigenas | Y1: Grupo Indigena | AB1: Generos | AE1: Estados civiles | AH1: Escolaridades | AK1: Entidades federatvas | AN1: Orige Afrodecendiente | AQ1: Municipios
A2: id | B2: sexo | D2: id | E2: discapacidad | G2: id | H2: asentamiento | J2: id | K2: vialidad | M2: id | N2: ocupación | P2: codigo pais | Q2: pais | S2: CVE_LOC | T2: NOM_LOC | V2: CLAVE_LENGUA | W2: LENGUA_INDIGENA | Y2: CLAVE_GRUPO | Z2: GRUPO | AB2: id | AC2: genero | AE2: id | AF2: estado_civil | AH2: id | AI2: escolaridad | AK2: CATALOG_KEY | AL2: ENTIDAD_FEDERATIVA | AN2: id | AO2: origen | AQ2: CVE_MUN | AR2: NOM_MUN
A3: 1 | B3: HOMBRE | D3: 1 | E3: NINGUNA | G3: 1 | H3: AEROPUERTO | J3: 1 | K3: AMPLIACIÓN | M3: 1 | N3: NINGUNA | P3: 101 | Q3: NAMIBIANA | S3: 1 | T3: Acatic | V3: 111 | W3: PAIPAI | Y3: 11 | Z3: YUMANO | AB3: 1 | AC3: HOMBRE | AE3: 1 | AF3: SOLTERA(O) | AH3: 1 | AI3: NINGUNA | AK3: 0 | AL3: EXTRANJERO | AN3: 0 | AO3: NO | AQ3: 1 | AR3: Acatic
A4: 2 | B4: MUJER | D4: 2 | E4: DISCAPACIDAD MOTORA | G4: 2 | H4: AMPLIACIÓN DE ASENTAMIENTO HUMANO | J4: 2 | K4: ANDADOR | M4: 2 | N4: JORNALERO/ALBAÑIL | P4: 103 | Q4: ANGOLESA | S4: 10 | T4: El Capadero (San Miguel de la Loza) | V4: 112 | W4: KILIWA | Y4: 12 | Z4: SERI | AB4: 2 | AC4: HOMBRE TRANS | AE4: 2 | AF4: CASADA(O) | AH4: 2 | AI4: PRIMARIA | AK4: 1 | AL4: AGUASCALIENTES | AN4: 1 | AO4: SI | AQ4: 10 | AR4: Atemajac de Brizuela
A5: 3 | B5: OTRO | D5: 3 | E5: DISCAPACIDAD VISUAL | G5: 3 | H5: BARRIO | J5: 3 | K5: AVENIDA | M5: 3 | N5: EMPLEADO/OBRERO | P5: 104 | Q5: ARGELIANA | S5: 102 | T5: Saltillo de Abajo | V5: 113 | W5: CUCAPÁ | Y5: 13 | Z5: TEQUISTLATECA | AB5: 3 | AC5: INTERSEXUAL | AE5: 3 | AF5: DIVORCIADA(O) | AH5: 3 | AI5: SECUNDARIA | AK5: 2 | AL5: BAJA CALIFORNIA | AQ5: 100 | AR5: Tomatlán
A6: 4 | B6: PREFIERO NO DECIR | D6: 4 | E6: DISCAPACIDAD AUDITIVA | G6: 4 | H6: CANTÓN | J6: 4 | K6: BOULEVARD | M6: 4 | N6: LABORES DEL HOGAR | P6: 105 | Q6: DE BENNIN | S6: 103 | T6: Sacamecate | V6: 114 | W6: COCHIMÍ | Y6: 20 | Z6: CHINANTECO | AB6: 4 | AC6: MUJER | AE6: 4 | AF6: UNION LIBRE | AH6: 4 | AI6: BACHILLERATO | AK6: 3 | AL6: BAJA CALIFORNIA SUR | AQ6: 101 | AR6: Tonalá
D7: 5 | E7: DISCAPACIDAD INTELECTUAL | G7: 5 | H7: CIUDAD | J7: 5 | K7: CALLE | M7: 5 | N7: ESTUDIOS | P7: 106 | Q7: BOTSWANESA | S7: 104 | T7: Codornices | V7: 115 | W7: KUMIAI | Y7: 21 | Z7: OJITECO | AB7: 5 | AC7: MUJER TRANS | AE7: 5 | AF7: VIUDA(O) | AH7: 5 | AI7: LICENCIATURA | AK7: 4 | AL7: CAMPECHE | AQ7: 102 | AR7: Tonaya
D8: 6 | E8: DISCAPACIDAD PSICOSOCIAL | G8: 6 | H8: CIUDAD INDUSTRIAL | J8: 6 | K8: CALLEJÓN | M8: 6 | N8: NEGOCIO PROPIO | P8: 107 | Q8: BURUNDESA | S8: 105 | T8: Las Tepozas | V8: 121 | W8: SERI | Y8: 22 | Z8: DE QUIOTEPEC | AB8: 6 | AC8: MUXE | AE8: 6 | AF8: SEPARADA(O) | AH8: 6 | AI8: MAESTRÍA | AK8: 5 | AL8: COAHUILA DE ZARAGOZA | AQ8: 103 | AR8: Tonila
D9: 7 | E9: DISCAPACIDAD MÚLTIPLE | G9: 7 | H9: COLONIA | J9: 7 | K9: CALZADA | M9: 7 | N9: DEPORTE | P9: 108 | Q9: DE CABO VERDE | S9: 106 | T9: La Sosa | V9: 131 | W9: CHONTAL DE OAXACA | Y9: 23 | Z9: DE PALANTLA | AB9: 7 | AC9: NO BINARIO | AE9: 7 | AF9: PREFIERO NO DECIR | AH9: 7 | AI9: DOCTORADO | AK9: 6 | AL9: COLIMA | AQ9: 104 | AR9: Totatiche
D10: 8 | E10: LIMITACIÓN MOTORA | G10: 8 | H10: CONDOMINIO | J10: 8 | K10: CERRADA | M10: 8 | N10: JUBILADO | P10: 109 | Q10: COMORENSE | S10: 107 | T10: Agropecuaria Calderón | V10: 200 | W10: CHINANTECO | Y10: 24 | Z10: DE LALANA | AB10: 8 | AC10: PREFIERO NO DECIR | AH10: 8 | AI10: PREESCOLAR | AK10: 7 | AL10: CHIAPAS | AQ10: 105 | AR10: Tototlán
D11: 9 | E11: LIMITACIÓN VISUAL | G11: 9 | H11: CONJUNTO HABITACIONAL | J11: 9 | K11: CIRCUITO | M11: 18 | N11: FUNCIONARIOS, DIRECTORES Y JEFES | P11: 110 | Q11: CONGOLESA | S11: 108 | T11: Las Amapolas | V11: 211 | W11: CHINANTECO DE OJITLÁN | Y11: 31 | Z11: PAMEANO | AB11: 9 | AC11: OTRO | AH11: 9 | AI11: ESPECIALIDAD | AK11: 8 | AL11: CHIHUAHUA | AQ11: 106 | AR11: Tuxcacuesco
D12: 10 | E12: LIMITACIÓN AUDITIVA | G12: 10 | H12: CORREDOR INDUSTRIAL | J12: 10 | K12: CIRCUNVALACIÓN | M12: 19 | N12: PROFESIONISTAS Y TÉCNICOS | P12: 111 | Q12: MARFILEÑA | S12: 109 | T12: Los Dos Pilares | V12: 212 | W12: CHINANTECO DE USILA | Y12: 32 | Z12: CHICHIMECA | AK12: 9 | AL12: CIUDAD DE MÉXICO | AQ12: 107 | AR12: Tuxcueca
D13: 11 | E13: LIMITACIÓN INTELECTUAL | G13: 11 | H13: COTO | J13: 11 | K13: CONTINUACIÓN | M13: 20 | N13: TRABAJADORES AUXILIARES EN ACTIVIDADES ADMINISTRATIVAS | P13: 112 | Q13: CHADIANA | S13: 11 | T13: Carricillo | V13: 221 | W13: CHINANTECO DE QUIOTEPEC | Y13: 33 | Z13: OTOMIANO | AK13: 10 | AL13: DURANGO | AQ13: 108 | AR13: Tuxpan
D14: 12 | E14: LIMITACIÓN PSICOSOCIAL | G14: 12 | H14: CUARTEL | J14: 12 | K14: CORREDOR | M14: 21 | N14: COMERCIANTES, EMPLEADOS EN VENTAS Y AGENTES DE VENTAS | P14: 113 | Q14: DE DJIBOUTI | S14: 111 | T14: Las Barranquitas | V14: 222 | W14: CHINANTECO DE YOLOX | Y14: 34 | Z14: MATLAZINCANO | AK14: 11 | AL14: GUANAJUATO | AQ14: 109 | AR14: Unión de San Antonio
D15: 13 | E15: LIMITACIÓN MÚLTIPLE | G15: 13 | H15: EJIDO | J15: 13 | K15: DIAGONAL | M15: 22 | N15: TRABAJADORES EN SERVICIOS PERSONALES Y DE VIGILANCIA | P15: 114 | Q15: EGIPCIA | S15: 112 | T15: La Calesa (Plan de Calderón) | V15: 223 | W15: CHINANTECO DE SOCHIAPAN | Y15: 40 | Z15: ZAPOTECO | AK15: 12 | AL15: GUERRERO | AQ15: 11 | AR15: Atengo
G16: 14 | H16: EXHACIENDA | J16: 14 | K16: EJE VIAL | M16: 23 | N16: TRABAJADORES EN ACTIVIDADES AGRÍCOLAS, GANADERAS, FORESTALES, CAZA Y PESCA | P16: 115 | Q16: ETIOPE | S16: 113 | T16: Cañada Honda | V16: 231 | W16: CHINANTECO DE PALANTLA | Y16: 41 | Z16: SERRANO NORTEÑO | AK16: 13 | AL16: HIDALGO | AQ16: 110 | AR16: Unión de Tula
G17: 15 | H17: FRACCIÓN | J17: 15 | K17: PASAJE | M17: 24 | N17: TRABAJADORES ARTESANALES, EN LA CONSTRUCCIÓN Y OTROS OFICIOS | P17: 116 | Q17: GABONESA | S17: 114 | T17: Tepatitlán [Club Cazadores] | V17: 232 | W17: CHINANTECO | Y17: 42 | Z17: DE LOS VALLES | AK17: 14 | AL17: JALISCO | AQ17: 111 | AR17: Valle de Guadalupe
G18: 16 | H18: FRACCIONAMIENTO | J18: 16 | K18: PEATONAL | M18: 25 | N18: OPERADORES DE MAQUINARIA INDUSTRIAL, ENSAMBLADORES, CHOFERES Y CONDUCTORES DE TRANSPORTE | P18: 117 | Q18: GAMBIANA | S18: 115 | T18: Cofradía Chica | V18: 241 | W18: CHINANTECO DE LALANA | Y18: 43 | Z18: SUREÑO | AK18: 15 | AL18: MÉXICO | AQ18: 112 | AR18: Valle de Juárez
G19: 17 | H19: GRANJA | J19: 17 | K19: PERIFÉRICO | M19: 26 | N19: TRABAJADORES EN ACTIVIDADES ELEMENTALES Y DE APOYO | P19: 118 | Q19: GHANATA | S19: 116 | T19: La Copetona | V19: 242 | W19: CHINANTECO DE LATANI | Y19: 44 | Z19: CHATINO | AK19: 16 | AL19: MICHOACÁN DE OCAMPO | AQ19: 113 | AR19: San Gabriel
G20: 18 | H20: HACIENDA | J20: 18 | K20: PRIVADA | P20: 119 | Q20: GUINEA | S20: 117 | T20: La Escopeta | V20: 243 | W20: CHINANTECO DE PETLAPA | Y20: 45 | Z20: MIXTECO | AK20: 17 | AL20: MORELOS | AQ20: 114 | AR20: Villa Corona
G21: 19 | H21: INGENIO | J21: 19 | K21: PROLONGACIÓN | P21: 120 | Q21: GUINEA | S21: 118 | T21: La Esperanza | V21: 311 | W21: PAME | Y21: 46 | Z21: CUICATECO | AK21: 18 | AL21: NAYARIT | AQ21: 115 | AR21: Villa Guerrero
G22: 20 | H22: MANZANA | J22: 20 | K22: RETORNO | P22: 121 | Q22: GUINEA ECUATORIANA | S22: 119 | T22: GENPRO [La Lechonera] | V22: 321 | W22: CHICHIMECA JONAZ | Y22: 47 | Z22: TRIQUE | AK22: 19 | AL22: NUEVO LEÓN | AQ22: 116 | AR22: Villa Hidalgo
G23: 21 | H23: PARAJE | J23: 21 | K23: VIADUCTO | P23: 122 | Q23: LIBIA | S23: 12 | T23: Ceja de Ramblas | V23: 331 | W23: OTOMÍ | Y23: 48 | Z23: AMUZGO | AK23: 20 | AL23: OAXACA | AQ23: 117 | AR23: Cañadas de Obregón
G24: 22 | H24: PARQUE INDUSTRIAL | J24: 22 | K24: NINGUNO | P24: 123 | Q24: KENIANA | S24: 120 | T24: Verde Valle [Granja] | V24: 332 | W24: MAZAHUA | Y24: 49 | Z24: MAZATECANO | AK24: 21 | AL24: PUEBLA | AQ24: 118 | AR24: Yahualica de González Gallo
G25: 23 | H25: PRIVADA DE ASENTAMIENTO | J25: 23 | K25: CARRETERA | P25: 124 | Q25: LESOTHENSE | S25: 121 | T25: El Refugio [Granja] | V25: 341 | W25: MATLATZINCA | Y25: 51 | Z25: HUAVE | AK25: 22 | AL25: QUERÉTARO | AQ25: 119 | AR25: Zacoalco de Torres
G26: 24 | H26: PROLONGACIÓN DE ASENTAMIENTO HUMANO | J26: 24 | K26: BRECHA | P26: 125 | Q26: LIBERIANA | S26: 122 | T26: Ninguno [Granja Rancho Nuevo] | V26: 342 | W26: OCUILTECO (TLAHUICA) | Y26: 61 | Z26: TLAPANECA | AK26: 23 | AL26: QUINTANA ROO | AQ26: 12 | AR26: Atenguillo
G27: 25 | H27: PUEBLO | J27: 25 | K27: CAMINO | P27: 127 | Q27: MALAWIANA | S27: 123 | T27: La Joya (Avícola la Joya) | V27: 400 | W27: ZAPOTECO | Y27: 71 | Z27: TOTONACA | AK27: 24 | AL27: SAN LUIS POTOSÍ | AQ27: 120 | AR27: Zapopan
G28: 26 | H28: PUERTO | J28: 26 | K28: TERRACERÍA | P28: 128 | Q28: MALIENSE | S28: 126 | T28: La Majada | V28: 411 | W28: ZAPOTECO DE IXTLÁN | Y28: 80 | Z28: POPOLUCA | AK28: 25 | AL28: SINALOA | AQ28: 121 | AR28: Zapotiltic
G29: 27 | H29: RANCHERÍA | J29: 27 | K29: VEREDA | P29: 129 | Q29: MARROQUI | S29: 127 | T29: Las Mesas | V29: 412 | W29: ZAPOTECO VIJANO | Y29: 81 | Z29: MIXE | AK29: 26 | AL29: SONORA | AQ29: 122 | AR29: Zapotitlán de Vadillo
G30: 28 | H30: RANCHO | J30: 28 | K30: ACUÁTICA | P30: 130 | Q30: MAURICIANA | S30: 128 | T30: La Mojonera | V30: 413 | W30: ZAPOTECO DEL RINCÓN | Y30: 82 | Z30: ZOQUE | AK30: 27 | AL30: TABASCO | AQ30: 123 | AR30: Zapotlán del Rey
G31: 29 | H31: REGIÓN | J31: 29 | K31: ARROYO | P31: 131 | Q31: MAURITANA | S31: 129 | T31: La Ordeña | V31: 421 | W31: ZAPOTECO VALLISTA | Y31: 91 | Z31: DEL GOLFO | AK31: 28 | AL31: TAMAULIPAS | AQ31: 124 | AR31: Zapotlanejo
... G37: 35 | H37: UNIDAD | J37: 35 | K37: MARÍTIMA | P37: 137 | Q37: TANZANIANA | S37: 135 | T37: El Saltillo | V37: 442 | W37: PAPABUCO | Y37: 97 | Z37: QUICHEANO | AK37: 99 | AL37: SE IGNORA | AQ37: 17 | AR37: Ayutla
G38: 36 | H38: UNIDAD HABITACIONAL | J38: 36 | K38: RÍO | P38: 139 | Q38: RWANDESA | S38: 136 | T38: Santo Domingo de Arriba | V38: 450 | W38: MIXTECO | Y38: 98 | Z38: K’EKCHÍ | AQ38: 18 | AR38: La Barca
G39: 37 | H39: VILLA | P39: 140 | Q39: DEL SAHARA | S39: 137 | T39: El Tanque | V39: 451 | W39: MIXTECO DE LA COSTA | Y39: 101 | Z39: PIMANO | AQ39: 19 | AR39: Bolaños
G40: 38 | H40: ZONA FEDERAL | P40: 141 | Q40: DE SANTO TOME | S40: 138 | T40: Tierra Blanca | V40: 452 | W40: MIXTECO DE LA MIXTECA ALTA | Y40: 102 | Z40: TARAHUMAREÑO | AQ40: 2 | AR40: Acatlán de Juárez
G41: 39 | H41: ZONA INDUSTRIAL | P41: 142 | Q41: SENEGALESA | S41: 139 | T41: Las Tortugas | V41: 453 | W41: MIXTECO DE LA MIXTECA BAJA | Y41: 103 | Z41: HUICHOLEÑO | AQ41: 20 | AR41: Cabo Corrientes
G42: 40 | H42: ZONA MILITAR | P42: 143 | Q42: DE SEYCHELLES | S42: 14 | T42: El Colomo | V42: 454 | W42: MIXTECO DE LA ZONA MAZATECA | Y42: 104 | Z42: AZTECANO | AQ42: 21 | AR42: Casimiro Castillo
G43: 41 | H43: NINGUNO | P43: 144 | Q43: SIERRA LEONESA | S43: 140 | T43: El Roble | V43: 455 | W43: MIXTECO DE PUEBLA | Y43: 111 | Z43: TARASCO | AQ43: 22 | AR43: Cihuatlán
G44: 42 | H44: ZONA NAVAL | P44: 145 | Q44: SOMALI | S44: 141 | T44: San Pablo | V44: 456 | W44: TACUATE | Y44: 121 | Z44: ALGONQUINO | AQ44: 23 | AR44: Zapotlán el Grande
P45: 146 | Q45: SUDAFRICANA | S45: 142 | T45: Acatic (Colonia la Prepa) | V45: 461 | W45: CUICATECO | Y45: 131 | Z45: ESPECIAL | AQ45: 24 | AR45: Cocula
...

Sheet CAT
A1: Sexos | D1: Discapacidades | G1: Asentamientos | J1: Vialidades | M1: Ocupaciones | P1: Nacionalidades | S1: Localidades | V1: Lenguas indigenas | Y1: Grupo Indigena | AB1: Generos | AE1: Estados civiles | AH1: Escolaridades | AK1: Entidades federatvas | AN1: Orige Afrodecendiente | AQ1: Municipios
A2: id | B2: sexo | D2: id | E2: discapacidad | G2: id | H2: asentamiento | J2: id | K2: vialidad | M2: id | N2: ocupación | P2: codigo pais | Q2: pais | S2: CVE_LOC | T2: NOM_LOC | V2: CLAVE_LENGUA | W2: LENGUA_INDIGENA | Y2: CLAVE_GRUPO | Z2: GRUPO | AB2: id | AC2: genero | AE2: id | AF2: estado_civil | AH2: id | AI2: escolaridad | AK2: CATALOG_KEY | AL2: ENTIDAD_FEDERATIVA | AN2: id | AO2: origen | AQ2: CVE_MUN | AR2: NOM_MUN
A3: 1 | B3: HOMBRE | D3: 1 | E3: NINGUNA | G3: 1 | H3: AEROPUERTO | J3: 1 | K3: AMPLIACIÓN | M3: 1 | N3: NINGUNA | P3: 101 | Q3: NAMIBIANA | S3: 676 | T3: 16 de Septiembre (Rancho las Tejas) | V3: 111 | W3: PAIPAI | Y3: 11 | Z3: YUMANO | AB3: 1 | AC3: HOMBRE | AE3: 1 | AF3: SOLTERA(O) | AH3: 1 | AI3: NINGUNA | AK3: 0 | AL3: EXTRANJERO | AN3: 0 | AO3: NO | AQ3: 1 | AR3: Acatic
A4: 2 | B4: MUJER | D4: 2 | E4: DISCAPACIDAD MOTORA | G4: 2 | H4: AMPLIACIÓN DE ASENTAMIENTO HUMANO | J4: 2 | K4: ANDADOR | M4: 2 | N4: JORNALERO/ALBAÑIL | P4: 103 | Q4: ANGOLESA | S4: 396 | T4: Abandono de Abajo | V4: 112 | W4: KILIWA | Y4: 12 | Z4: SERI | AB4: 2 | AC4: HOMBRE TRANS | AE4: 2 | AF4: CASADA(O) | AH4: 2 | AI4: PRIMARIA | AK4: 1 | AL4: AGUASCALIENTES | AN4: 1 | AO4: SI | AQ4: 10 | AR4: Atemajac de Brizuela
A5: 3 | B5: OTRO | D5: 3 | E5: DISCAPACIDAD VISUAL | G5: 3 | H5: BARRIO | J5: 3 | K5: AVENIDA | M5: 3 | N5: EMPLEADO/OBRERO | P5: 104 | Q5: ARGELIANA | S5: 65 | T5: Abasolo (La Otra Casa) | V5: 113 | W5: CUCAPÁ | Y5: 13 | Z5: TEQUISTLATECA | AB5: 3 | AC5: INTERSEXUAL | AE5: 3 | AF5: DIVORCIADA(O) | AH5: 3 | AI5: SECUNDARIA | AK5: 2 | AL5: BAJA CALIFORNIA | AQ5: 100 | AR5: Tomatlán
A6: 4 | B6: PREFIERO NO DECIR | D6: 4 | E6: DISCAPACIDAD AUDITIVA | G6: 4 | H6: CANTÓN | J6: 4 | K6: BOULEVARD | M6: 4 | N6: LABORES DEL HOGAR | P6: 105 | Q6: DE BENNIN | S6: 234 | T6: Abel González | V6: 114 | W6: COCHIMÍ | Y6: 20 | Z6: CHINANTECO | AB6: 4 | AC6: MUJER | AE6: 4 | AF6: UNION LIBRE | AH6: 4 | AI6: BACHILLERATO | AK6: 3 | AL6: BAJA CALIFORNIA SUR | AQ6: 101 | AR6: Tonalá
D7: 5 | E7: DISCAPACIDAD INTELECTUAL | G7: 5 | H7: CIUDAD | J7: 5 | K7: CALLE | M7: 5 | N7: ESTUDIOS | P7: 106 | Q7: BOTSWANESA | S7: 114 | T7: Abelino Virgen | V7: 115 | W7: KUMIAI | Y7: 21 | Z7: OJITECO | AB7: 5 | AC7: MUJER TRANS | AE7: 5 | AF7: VIUDA(O) | AH7: 5 | AI7: LICENCIATURA | AK7: 4 | AL7: CAMPECHE | AQ7: 102 | AR7: Tonaya
D8: 6 | E8: DISCAPACIDAD PSICOSOCIAL | G8: 6 | H8: CIUDAD INDUSTRIAL | J8: 6 | K8: CALLEJÓN | M8: 6 | N8: NEGOCIO PROPIO | P8: 107 | Q8: BURUNDESA | S8: 54 | T8: Aberrusco | V8: 121 | W8: SERI | Y8: 22 | Z8: DE QUIOTEPEC | AB8: 6 | AC8: MUXE | AE8: 6 | AF8: SEPARADA(O) | AH8: 6 | AI8: MAESTRÍA | AK8: 5 | AL8: COAHUILA DE ZARAGOZA | AQ8: 103 | AR8: Tonila
D9: 7 | E9: DISCAPACIDAD MÚLTIPLE | G9: 7 | H9: COLONIA | J9: 7 | K9: CALZADA | M9: 7 | N9: DEPORTE | P9: 108 | Q9: DE CABO VERDE | S9: 221 | T9: Acacias | V9: 131 | W9: CHONTAL DE OAXACA | Y9: 23 | Z9: DE PALANTLA | AB9: 7 | AC9: NO BINARIO | AE9: 7 | AF9: PREFIERO NO DECIR | AH9: 7 | AI9: DOCTORADO | AK9: 6 | AL9: COLIMA | AQ9: 104 | AR9: Totatiche
D10: 8 | E10: LIMITACIÓN MOTORA | G10: 8 | H10: CONDOMINIO | J10: 8 | K10: CERRADA | M10: 8 | N10: JUBILADO | P10: 109 | Q10: COMORENSE | S10: 2 | T10: Acahuales | V10: 200 | W10: CHINANTECO | Y10: 24 | Z10: DE LALANA | AB10: 8 | AC10: PREFIERO NO DECIR | AH10: 8 | AI10: PREESCOLAR | AK10: 7 | AL10: CHIAPAS | AQ10: 105 | AR10: Tototlán
D11: 9 | E11: LIMITACIÓN VISUAL | G11: 9 | H11: CONJUNTO HABITACIONAL | J11: 9 | K11: CIRCUITO | M11: 18 | N11: FUNCIONARIOS, DIRECTORES Y JEFES | P11: 110 | Q11: CONGOLESA | S11: 2 | T11: Acahuales (San Miguel de Acahuales) | V11: 211 | W11: CHINANTECO DE OJITLÁN | Y11: 31 | Z11: PAMEANO | AB11: 9 | AC11: OTRO | AH11: 9 | AI11: ESPECIALIDAD | AK11: 8 | AL11: CHIHUAHUA | AQ11: 106 | AR11: Tuxcacuesco
D12: 10 | E12: LIMITACIÓN AUDITIVA | G12: 10 | H12: CORREDOR INDUSTRIAL | J12: 10 | K12: CIRCUNVALACIÓN | M12: 19 | N12: PROFESIONISTAS Y TÉCNICOS | P12: 111 | Q12: MARFILEÑA | S12: 2 | T12: Acajale (El Acajal) | V12: 212 | W12: CHINANTECO DE USILA | Y12: 32 | Z12: CHICHIMECA | AK12: 9 | AL12: CIUDAD DE MÉXICO | AQ12: 107 | AR12: Tuxcueca
D13: 11 | E13: LIMITACIÓN INTELECTUAL | G13: 11 | H13: COTO | J13: 11 | K13: CONTINUACIÓN | M13: 20 | N13: TRABAJADORES AUXILIARES EN ACTIVIDADES ADMINISTRATIVAS | P13: 112 | Q13: CHADIANA | S13: 553 | T13: Acajilote | V13: 221 | W13: CHINANTECO DE QUIOTEPEC | Y13: 33 | Z13: OTOMIANO | AK13: 10 | AL13: DURANGO | AQ13: 108 | AR13: Tuxpan
D14: 12 | E14: LIMITACIÓN PSICOSOCIAL | G14: 12 | H14: CUARTEL | J14: 12 | K14: CORREDOR | M14: 21 | N14: COMERCIANTES, EMPLEADOS EN VENTAS Y AGENTES DE VENTAS | P14: 113 | Q14: DE DJIBOUTI | S14: 47 | T14: Acapulquito | V14: 222 | W14: CHINANTECO DE YOLOX | Y14: 34 | Z14: MATLAZINCANO | AK14: 11 | AL14: GUANAJUATO | AQ14: 109 | AR14: Unión de San Antonio
D15: 13 | E15: LIMITACIÓN MÚLTIPLE | G15: 13 | H15: EJIDO | J15: 13 | K15: DIAGONAL | M15: 22 | N15: TRABAJADORES EN SERVICIOS PERSONALES Y DE VIGILANCIA | P15: 114 | Q15: EGIPCIA | S15: 2 | T15: Acasico | V15: 223 | W15: CHINANTECO DE SOCHIAPAN | Y15: 40 | Z15: ZAPOTECO | AK15: 12 | AL15: GUERRERO | AQ15: 11 | AR15: Atengo
G16: 14 | H16: EXHACIENDA | J16: 14 | K16: EJE VIAL | M16: 23 | N16: TRABAJADORES EN ACTIVIDADES AGRÍCOLAS, GANADERAS, FORESTALES, CAZA Y PESCA | P16: 115 | Q16: ETIOPE | S16: 3 | T16: Acaspoles | V16: 231 | W16: CHINANTECO DE PALANTLA | Y16: 41 | Z16: SERRANO NORTEÑO | AK16: 13 | AL16: HIDALGO | AQ16: 110 | AR16: Unión de Tula
G17: 15 | H17: FRACCIÓN | J17: 15 | K17: PASAJE | M17: 24 | N17: TRABAJADORES ARTESANALES, EN LA CONSTRUCCIÓN Y OTROS OFICIOS | P17: 116 | Q17: GABONESA | S17: 193 | T17: Acaspoluca | V17: 232 | W17: CHINANTECO | Y17: 42 | Z17: DE LOS VALLES | AK17: 14 | AL17: JALISCO | AQ17: 111 | AR17: Valle de Guadalupe
G18: 16 | H18: FRACCIONAMIENTO | J18: 16 | K18: PEATONAL | M18: 25 | N18: OPERADORES DE MAQUINARIA INDUSTRIAL, ENSAMBLADORES, CHOFERES Y CONDUCTORES DE TRANSPORTE | P18: 117 | Q18: GAMBIANA | S18: 2 | T18: Acaspulco | V18: 241 | W18: CHINANTECO DE LALANA | Y18: 43 | Z18: SUREÑO | AK18: 15 | AL18: MÉXICO | AQ18: 112 | AR18: Valle de Juárez
G19: 17 | H19: GRANJA | J19: 17 | K19: PERIFÉRICO | M19: 26 | N19: TRABAJADORES EN ACTIVIDADES ELEMENTALES Y DE APOYO | P19: 118 | Q19: GHANATA | S19: 3 | T19: Acaspulquillo | V19: 242 | W19: CHINANTECO DE LATANI | Y19: 44 | Z19: CHATINO | AK19: 16 | AL19: MICHOACÁN DE OCAMPO | AQ19: 113 | AR19: San Gabriel
G20: 18 | H20: HACIENDA | J20: 18 | K20: PRIVADA | P20: 119 | Q20: GUINEA | S20: 611 | T20: Acatán | V20: 243 | W20: CHINANTECO DE PETLAPA | Y20: 45 | Z20: MIXTECO | AK20: 17 | AL20: MORELOS | AQ20: 114 | AR20: Villa Corona
G21: 19 | H21: INGENIO | J21: 19 | K21: PROLONGACIÓN | P21: 120 | Q21: GUINEA | S21: 616 | T21: Acatan de Abajo | V21: 311 | W21: PAME | Y21: 46 | Z21: CUICATECO | AK21: 18 | AL21: NAYARIT | AQ21: 115 | AR21: Villa Guerrero
G22: 20 | H22: MANZANA | J22: 20 | K22: RETORNO | P22: 121 | Q22: GUINEA ECUATORIANA | S22: 4 | T22: Acatepulco | V22: 321 | W22: CHICHIMECA JONAZ | Y22: 47 | Z22: TRIQUE | AK22: 19 | AL22: NUEVO LEÓN | AQ22: 116 | AR22: Villa Hidalgo
G23: 21 | H23: PARAJE | J23: 21 | K23: VIADUCTO | P23: 122 | Q23: LIBIA | S23: 1 | T23: Acatic | V23: 331 | W23: OTOMÍ | Y23: 48 | Z23: AMUZGO | AK23: 20 | AL23: OAXACA | AQ23: 117 | AR23: Cañadas de Obregón
G24: 22 | H24: PARQUE INDUSTRIAL | J24: 22 | K24: NINGUNO | P24: 123 | Q24: KENIANA | S24: 142 | T24: Acatic (Colonia la Prepa) | V24: 332 | W24: MAZAHUA | Y24: 49 | Z24: MAZATECANO | AK24: 21 | AL24: PUEBLA | AQ24: 118 | AR24: Yahualica de González Gallo
G25: 23 | H25: PRIVADA DE ASENTAMIENTO | J25: 23 | K25: CARRETERA | P25: 124 | Q25: LESOTHENSE | S25: 2 | T25: Acatic (San Francisco) | V25: 341 | W25: MATLATZINCA | Y25: 51 | Z25: HUAVE | AK25: 22 | AL25: QUERÉTARO | AQ25: 119 | AR25: Zacoalco de Torres
G26: 24 | H26: PROLONGACIÓN DE ASENTAMIENTO HUMANO | J26: 24 | K26: BRECHA | P26: 125 | Q26: LIBERIANA | S26: 2 | T26: Acatica | V26: 342 | W26: OCUILTECO (TLAHUICA) | Y26: 61 | Z26: TLAPANECA | AK26: 23 | AL26: QUINTANA ROO | AQ26: 12 | AR26: Atenguillo
G27: 25 | H27: PUEBLO | J27: 25 | K27: CAMINO | P27: 127 | Q27: MALAWIANA | S27: 602 | T27: Acatita | V27: 400 | W27: ZAPOTECO | Y27: 71 | Z27: TOTONACA | AK27: 24 | AL27: SAN LUIS POTOSÍ | AQ27: 120 | AR27: Zapopan
G28: 26 | H28: PUERTO | J28: 26 | K28: TERRACERÍA | P28: 128 | Q28: MALIENSE | S28: 978 | T28: Acatita Chica | V28: 411 | W28: ZAPOTECO DE IXTLÁN | Y28: 80 | Z28: POPOLUCA | AK28: 25 | AL28: SINALOA | AQ28: 121 | AR28: Zapotiltic
G29: 27 | H29: RANCHERÍA | J29: 27 | K29: VEREDA | P29: 129 | Q29: MARROQUI | S29: 2 | T29: Acatitlán | V29: 412 | W29: ZAPOTECO VIJANO | Y29: 81 | Z29: MIXE | AK29: 26 | AL29: SONORA | AQ29: 122 | AR29: Zapotitlán de Vadillo
G30: 28 | H30: RANCHO | J30: 28 | K30: ACUÁTICA | P30: 130 | Q30: MAURICIANA | S30: 60 | T30: Acatitlán (Los Ranchitos) | V30: 413 | W30: ZAPOTECO DEL RINCÓN | Y30: 82 | Z30: ZOQUE | AK30: 27 | AL30: TABASCO | AQ30: 123 | AR30: Zapotlán del Rey
G31: 29 | H31: REGIÓN | J31: 29 | K31: ARROYO | P31: 131 | Q31: MAURITANA | S31: 1 | T31: Acatlán de Juárez | V31: 421 | W31: ZAPOTECO VALLISTA | Y31: 91 | Z31: DEL GOLFO | AK31: 28 | AL31: TAMAULIPAS | AQ31: 124 | AR31: Zapotlanejo
... G37: 35 | H37: UNIDAD | J37: 35 | K37: MARÍTIMA | P37: 137 | Q37: TANZANIANA | S37: 327 | T37: Acosta | V37: 442 | W37: PAPABUCO | Y37: 97 | Z37: QUICHEANO | AK37: 99 | AL37: SE IGNORA | AQ37: 17 | AR37: Ayutla
G38: 36 | H38: UNIDAD HABITACIONAL | J38: 36 | K38: RÍO | P38: 139 | Q38: RWANDESA | S38: 467 | T38: Acosta [Granja] | V38: 450 | W38: MIXTECO | Y38: 98 | Z38: K’EKCHÍ | AQ38: 18 | AR38: La Barca
G39: 37 | H39: VILLA | P39: 140 | Q39: DEL SAHARA | S39: 473 | T39: Acostalpa | V39: 451 | W39: MIXTECO DE LA COSTA | Y39: 101 | Z39: PIMANO | AQ39: 19 | AR39: Bolaños
G40: 38 | H40: ZONA FEDERAL | P40: 141 | Q40: DE SANTO TOME | S40: 89 | T40: Acualaxco | V40: 452 | W40: MIXTECO DE LA MIXTECA ALTA | Y40: 102 | Z40: TARAHUMAREÑO | AQ40: 2 | AR40: Acatlán de Juárez
G41: 39 | H41: ZONA INDUSTRIAL | P41: 142 | Q41: SENEGALESA | S41: 620 | T41: Acueducto [Fraccionamiento] | V41: 453 | W41: MIXTECO DE LA MIXTECA BAJA | Y41: 103 | Z41: HUICHOLEÑO | AQ41: 20 | AR41: Cabo Corrientes
G42: 40 | H42: ZONA MILITAR | P42: 143 | Q42: DE SEYCHELLES | S42: 11 | T42: Acuícola las Garzas (El Camichín) | V42: 454 | W42: MIXTECO DE LA ZONA MAZATECA | Y42: 104 | Z42: AZTECANO | AQ42: 21 | AR42: Casimiro Castillo
G43: 41 | H43: NINGUNO | P43: 144 | Q43: SIERRA LEONESA | S43: 2 | T43: Acúmbaro | V43: 455 | W43: MIXTECO DE PUEBLA | Y43: 111 | Z43: TARASCO | AQ43: 22 | AR43: Cihuatlán
G44: 42 | H44: ZONA NAVAL | P44: 145 | Q44: SOMALI | S44: 266 | T44: Adelante Mi Palomo | V44: 456 | W44: TACUATE | Y44: 121 | Z44: ALGONQUINO | AQ44: 23 | AR44: Zapotlán el Grande
P45: 146 | Q45: SUDAFRICANA | S45: 462 | T45: Adi [Granja] | V45: 461 | W45: CUICATECO | Y45: 131 | Z45: ESPECIAL | AQ45: 24 | AR45: Cocula
...

Sheet SERVICIOS
A1: APOYO SOCIAL (RACIONES) | B1: SERVICIOS DE SALUD | C1: TRABAJO SOCIAL | D1: SESIONES TALLERES Y ACTIVIDADES | E1: TRASLADOS | F1: ACTIVIDAD INTERGENERACIONAL | G1: PSICOLOGIA | H1: JURIDICO | I1: INGRESOS AL PADRON
A2: Desayunos | B2: Orientación Médica | C2: Valoraciones para Ingreso | D2: Deportivos y Activación Física: | E2: Visitas Domiciliarias y/o Traslados | F2: Encuentros Intergeneracionales | G2: Atención Integral | H2: Valoraciones para Ingreso | I2: Altas del mes
A3: Colaciones Matutinas | B3: Consulta Médica | C3: Gestiones para Apoyos u Otros Servicios | D3: Acondicionamiento Físico | E3: Acompañamiento y/o Traslados a citas médicas | F3: Encuentros y Eventos Comunitarios | G3: Psicología | H3: Atención Individual | I3: Bajas del mes
A4: Comidas | B4: Consultas o Interconsultas | C4: Actualización de Expedientes y Notas | D4: Ejercicio en Silla | E4: Total de Traslados | F4: Evento del adulto mayor | G4: Atención Individual | H4: Seguimientos | I4: Altas del mes
A5: Colaciones Vespertinas | B5: Valoraciones Médicas | C5: Atención a Casos de Dirección | D5: Yoga | E5: Asistencia de Camiones | G5: Seguimientos | H5: Intervenciones en Crisis | I5: Bajas
A6: Cenas | B6: Atención en Urgencias y Emergencias Médicas | C6: Aplicación de Estudio Socioeconómico | D6: Yoga en Silla | E6: Visitas a Grupo | G6: Intervenciones en Crisis | H6: Asesorías y Orientaciones | I6: Accesibilidad
A7: Raciones CAPAM | B7: Expedición y Actualización de Indicaciones Terapéuticas | C7: SICATS | D7: Yoga de la Risa | G7: Asesoras y Orientaciones Psicológicas | H7: Asesoras y Orientaciones | I7: Médico
B8: Signos Vitales | C8: Seguimiento con tutores de residentes | D8: Pilates | I8: Valoración
B9: Glucemia Capilar | C9: Notas de seguimiento | D9: Zumba | I9: Revaloraciones
B10: Inyecciones I.M. y/o Subcutánea | C10: Acciones Asistenciales | D10: Activación física
B11: Medicamentos I.V. y/o V.O. | C11: Entrega de bitácoras de asistencias | D11: Deporte
B12: Venoclisis | D12: Ping Pong
B13: Curación | D13: Torneo en Cachibol
B14: Vendajes | D14: Actividades Físicas, baile
B15: Nebulización | D15: Culturales, Expresión y Baile:
B16: Inhalaciones en Aerosol | D16: Guitarra principiantes
B17: Puntas Nasales | D17: Canto grupal
B18: Mascarilla con o sin Reservorio | D18: Taller de Canto
B19: Lavado Ótico | D19: Baile de Danzón
B20: Aplicación de Medicamentos Oftálmicos | D20: Danzón
B21: Colocación y/o Retiro de Sonda Foley | D21: Danzón en Línea
B22: Medios Físicos | D22: Baile en Línea
B23: Cuidados Hospitalarios | D23: Baile de Salsa
... B45: Medicina alternativa | D45: Dibujo
D46: Alebrijes
D47: Bisutería
D48: Bisutería en Hilo
D49: Técnica en Hoja Natural
D50: Velas
D51: Velas OXXO
D52: Globoflexia
D53: Fieltro
D54: Serpentina
D55: Pintura textil
D56: Foami
D57: Piñatas
... D97: Pláticas y Actividades Extras
